<?xml version="1.0"?>
<robot name="model">

    <material name="magenta">
        <color rgba="1 0 1 1"/>
    </material>
    <material name="yellow">
        <color rgba="1 1 0 1"/>
    </material>
    
    <link name="base_link">
        <visual>
            <geometry>
                <mesh filename="package://miapr_projekt/robot_mesh.stl" scale="0.5 0.5 0.5"/>
            </geometry>
            <material name="magenta"/>
        </visual>
        <collision>
            <geometry>
                <cylinder length="0.3" radius="0.15"/>
            </geometry>
        </collision>
        <inertial>
			<mass value="0.5"/>
			<inertia ixx="0.02625" ixy="0" ixz="0" iyy="0.0225" iyz="0" izz="0.02625"/>
		</inertial>
    </link>
    
    <link name="left_wheel">
        <visual>
            <geometry>
                <cylinder length="0.01" radius="0.04"/>
            </geometry>
            <origin rpy="1.57075 0 0"/>
            <material name="yellow"/>
        </visual>
        <collision>
            <origin rpy="1.57075 0 0" xyz="0 0 0"/>
            <geometry>
                <cylinder length="0.01" radius="0.04"/>
            </geometry>
        </collision>
        <inertial>
			<mass value="0.02"/>
			<inertia ixx="8e-06" ixy="0" ixz="0" iyy="1.6e-05" iyz="0" izz="8e-05"/>
		</inertial>
    </link>
    
    <joint name="left_wheel_joint" type="continuous">
        <parent link="base_link"/>
        <child link="left_wheel"/>
        <origin xyz="0 -0.1505 0.04"/>
        <axis xyz="0 1 0"/>
    </joint>
    
    <link name="right_wheel">
        <visual>
            <geometry>
                <cylinder length="0.01" radius="0.04"/>
            </geometry>
            <origin rpy="1.57075 0 0"/>
            <material name="yellow"/>
        </visual>
        <collision>
            <origin rpy="1.57075 0 0" xyz="0 0 0"/>
            <geometry>
                <cylinder length="0.01" radius="0.04"/>
            </geometry>
        </collision>
        <inertial>
			<mass value="0.02"/>
			<inertia ixx="8e-06" ixy="0" ixz="0" iyy="1.6e-05" iyz="0" izz="8e-05"/>
		</inertial>
    </link>
    
    <joint name="right_wheel_joint" type="continuous">
        <parent link="base_link"/>
        <child link="right_wheel"/>
        <origin xyz="0 0.1505 0.04"/>
        <axis xyz="0 1 0"/>
    </joint>
    
</robot>
